Workbook
Name Slicer_Functioning_Day: #N/A
Name Slicer_Holiday: #N/A
Name Slicer_Seasons: #N/A

Sheet SeoulBikeDataCleaned
A1: Date | B1: Rented Bike Count | C1: Hour | D1: Temperature(°C) | E1: Humidity(%) | F1: Wind speed (m/s) | G1: Visibility (10m) | H1: Dew point temperature(°C) | I1: Solar Radiation (MJ/m2) | J1: Rainfall(mm) | K1: Snowfall (cm) | L1: Seasons | M1: Holiday | N1: Functioning Day | O1: Month
A2: 43270 | B2: 3556 | C2: 18 | D2: 24 | E2: 57 | F2: 2.9 | G2: 1301 | H2: 15 | I2: 0.56 | J2: 0 | K2: 0 | L2: Summer | M2: No Holiday | N2: Yes | O2: =TEXT(A2,"mmm") -> Jun
A3: 43272 | B3: 3418 | C3: 18 | D3: 28 | E3: 43 | F3: 3 | G3: 1933 | H3: 14 | I3: 1.35 | J3: 0 | K3: 0 | L3: Summer | M3: No Holiday | N3: Yes | O3: =TEXT(A3,"mmm") -> Jun
A4: 43263 | B4: 3404 | C4: 18 | D4: 25 | E4: 53 | F4: 3.6 | G4: 2000 | H4: 14.6 | I4: 1.28 | J4: 0 | K4: 0 | L4: Summer | M4: No Holiday | N4: Yes | O4: =TEXT(A4,"mmm") -> Jun
A5: 43271 | B5: 3384 | C5: 18 | D5: 27 | E5: 55 | F5: 3.1 | G5: 1246 | H5: 17.1 | I5: 1.26 | J5: 0 | K5: 0 | L5: Summer | M5: No Holiday | N5: Yes | O5: =TEXT(A5,"mmm") -> Jun
A6: 43255 | B6: 3380 | C6: 18 | D6: 24 | E6: 48 | F6: 1.9 | G6: 1998 | H6: 12.6 | I6: 0.56 | J6: 0 | K6: 0 | L6: Summer | M6: No Holiday | N6: Yes | O6: =TEXT(A6,"mmm") -> Jun
A7: 43273 | B7: 3365 | C7: 18 | D7: 29 | E7: 27 | F7: 3.4 | G7: 1977 | H7: 8.3 | I7: 1.24 | J7: 0 | K7: 0 | L7: Summer | M7: No Holiday | N7: Yes | O7: =TEXT(A7,"mmm") -> Jun
A8: 43259 | B8: 3309 | C8: 18 | D8: 26 | E8: 54 | F8: 2.2 | G8: 1183 | H8: 16.1 | I8: 0.88 | J8: 0 | K8: 0 | L8: Summer | M8: No Holiday | N8: Yes | O8: =TEXT(A8,"mmm") -> Jun
A9: 43353 | B9: 3298 | C9: 18 | D9: 26 | E9: 42 | F9: 1.1 | G9: 2000 | H9: 11.9 | I9: 0.48 | J9: 0 | K9: 0 | L9: Autumn | M9: No Holiday | N9: Yes | O9: =TEXT(A9,"mmm") -> Sep
A10: 43360 | B10: 3277 | C10: 18 | D10: 25 | E10: 56 | F10: 2.8 | G10: 1992 | H10: 15.8 | I10: 0.54 | J10: 0 | K10: 0 | L10: Autumn | M10: No Holiday | N10: Yes | O10: =TEXT(A10,"mmm") -> Sep
A11: 43355 | B11: 3256 | C11: 18 | D11: 27 | E11: 44 | F11: 1.4 | G11: 2000 | H11: 13.6 | I11: 0.62 | J11: 0 | K11: 0 | L11: Autumn | M11: No Holiday | N11: Yes | O11: =TEXT(A11,"mmm") -> Sep
A12: 43250 | B12: 3251 | C12: 18 | D12: 24 | E12: 42 | F12: 2.1 | G12: 2000 | H12: 9.9 | I12: 1.23 | J12: 0 | K12: 0 | L12: Spring | M12: No Holiday | N12: Yes | O12: =TEXT(A12,"mmm") -> May
A13: 43248 | B13: 3245 | C13: 18 | D13: 26 | E13: 39 | F13: 2.7 | G13: 1950 | H13: 10.9 | I13: 1.07 | J13: 0 | K13: 0 | L13: Spring | M13: No Holiday | N13: Yes | O13: =TEXT(A13,"mmm") -> May
... A8761: 43407 | B8761: 0 | C8761: 8 | D8761: 5 | E8761: 75 | F8761: 0.4 | G8761: 905 | H8761: 1.3 | I8761: 0.11 | J8761: 0 | K8761: 0 | L8761: Autumn | M8761: No Holiday | N8761: No | O8761: =TEXT(A8761,"mmm") -> Nov

Sheet KPI
A2: KPI
A3: Column1 | B3: Column2
A4: 1.Total Rentals | B4: =SUM(SeoulBikeDataCleaned!B:B) -> 6172314
A5: 2.Average Daily Rentals | B5: =AVERAGE(SeoulBikeDataCleaned!B:B) -> 704.60205
A6: 3.Highest Rentals (daily) | B6: =MAX(SeoulBikeDataCleaned!B:B) -> 3556

Sheet Charts
A2: 1.Average Bike Rentals by Season
A4: Row Labels | B4: Average of Rented Bike Count
A5: Autumn | B5: 819.59799
A6: Spring | B6: 730.03125
A7: Summer | B7: 1034.0734
A8: Winter | B8: 225.5412
A9: Grand Total | B9: 704.60205
A12: 2. Total Rentals By Month
A14: Row Labels | B14: Sum of Rented Bike Count
A15: Jan | B15: 150006
A16: Feb | B16: 151833
A17: Mar | B17: 380594
A18: Apr | B18: 524227
A19: May | B19: 707088
A20: Jun | B20: 896887
A21: Jul | B21: 734460
A22: Aug | B22: 651887
A23: Sep | B23: 673612
A24: Oct | B24: 650675
A25: Nov | B25: 465715
A26: Dec | B26: 185330
A27: Grand Total | B27: 6172314
A30: 3.Rentals By Hour
A32: Row Labels | B32: Average of Rented Bike Count
A33: 18 | B33: 1502.926
A34: 19 | B34: 1195.1479
A35: 17 | B35: 1138.5096
A36: 20 | B36: 1068.9644
A37: 21 | B37: 1031.4493
A38: 8 | B38: 1015.7014
A39: 16 | B39: 930.62192
A40: 22 | B40: 922.79726
A41: 15 | B41: 829.1863
A42: 14 | B42: 758.82466
A43: 13 | B43: 733.24658
A44: 12 | B44: 699.4411
... A56: 4 | B56: 132.59178
A57: Grand Total | B57: 704.60205
A60: 4.Rentals vs Temperature
A76: 5.Rentals vs Rainfall
...

Sheet Sheet2
B5: Total Rentals | E5: Average Temperature | I5: Average Daily Rentals | M5: Highest Rentals | Q5: Average Humidity
B6: =KPI!B4 -> 6172314 | E6: =AVERAGE(SeoulBikeDataCleaned!D:D) -> 12.8871 | I6: =KPI!B5 -> 704.60205 | M6: =Table2[[#This Row],[Column2]] -> 3556 | Q6: =AVERAGE(SeoulBikeDataCleaned!E:E) -> 58.226256
